function wait(msec) {
  return new Promise((resolve) => setTimeout(resolve, msec));
}

const wait0 = () => wait(0);
const wait1 = () => wait(1000);
const wait2 = () => wait(2000);
const wait3 = () => wait(3000);

// ログ出力
const log = (v) => console.log(v);
const logA = (v) => console.log("A");
const logB = (v) => console.log("B");
const logC = (v) => console.log("C");

// 例外
const errX = () => {
  throw new Error("X");
};
const errY = () => {
  throw new Error("Y");
};
/*
awaitで上から終promiseが見たされるかで次に進まない。
そのため3s後にA→2秒後にB→1秒後にC
が表示される。
*/
async function h1() {
  try {
    await wait3();
    logA();
    await wait2();
    logB();
    await wait1();
    logC();
  } catch (e) {
    log(e.message);
  }
}
//await h1();

/*
new Promise内でエラーが発生してことでrejectになる
これによりcatvh文の中が動作するのでXが表示される
*/
function h2() {
  // NOTE: h3 との比較用
  new Promise(() => {
    errX();
  }).catch((e) => log(e.message));
}
// h2();

/*
asyncとawaitはセットで利用するものなので予想がつかなかった
実際に動作させると、asyncがついた状態ではエラーをキャッチすることができず、そのままエラーが発生した。
promiseの中にpromiseがあるという状態になることでこのような挙動になったと思う。
*/
function h3() {
  // NOTE: new Promise の引数が async function の場合、例外はどう扱われるだろう
  new Promise(async () => {
    errX();
  }).catch((e) => log(e.message));
}
//h3();

/*
変数定義したタイミングで動作するのでエラーをキャッチできない
実際に動かすとerr Yがそのままでてしまった。
await wait2().then にすればエラーをキャッチできる。
*/
async function h4() {
  // NOTE: 2つの例外は両方 catch できるか？
  try {
    const p1 = wait2().then(() => {
      errX();
    });
    const p2 = wait1().then(() => {
      errY();
    });
    //await p1;
    //await p2;
  } catch (e) {
    log(e.message);
  }
}

await h4();
